Workbook

Sheet Cost Sheet Elements
B3: Direct Materials | H3: Assumptions
B5: Component | C5: ₹ / Unit | H5: Annual production: 100,000 units
B6: Imported raw material | C6: 300 | H6: Monthly production: 8,333 units
B7: Domestic raw material | C7: 200 | H7: Base USD–INR: ₹83/USD
B8: Total Direct Materials | C8: 500 | H8: Purpose: Standard (normal) cost under stable conditions
B11: Direct Labour
B13: Component | C13: ₹ / Unit
B14: Production labour | C14: 80
B17: Manufacturing Overheads
B19: Component | C19: ₹ / Unit
B20: Power & fuel | C20: 45
B21: Repairs & maintenance | C21: 35
B22: Consumables | C22: 30
B23: Factory supervision | C23: 40
B24: Total Manufacturing OH | C24: 150
B27: Administrative Overheads
B29: Component | C29: ₹ / Unit
B30: Admin salaries & office costs | C30: 70
B33: Selling & Distribution Overheads (Semi-variable)
B35: Component | C35: ₹ / Unit
B36: S&D OH | C36: 100

Sheet Base Price
C3: Base per unit cost of imported Materials (in USD)
C5: Base Exchange Rate | E5: 87
C6: Import cost Base | E6: 300
C8: USD Cost Per Unit | E8: =E6/E5 -> 3.4482759
C9: monthly cost | E9: =E6*100000/12 -> 2500000

Sheet Cost Sheet
C2: Cost Sheet (monthly)
C4: Cost Head | D4: per unit | E4: Monthly Cost
C5: Direct Materials | D5: 500 | E5: =D5*100000/12 -> 4166666.7
C6: Direct Labour | D6: 80 | E6: =D6*100000/12 -> 666666.67
C7: Manufacturing OH | D7: 150 | E7: =D7*100000/12 -> 1250000
C8: Administrative OH | D8: 70 | E8: =D8*100000/12 -> 583333.33
C9: Selling & Distribution OH | D9: 100 | E9: =D9*100000/12 -> 833333.33
C10: TOTAL MONTHLY COST | D10: =SUM(D5:D9) -> 900 | E10: =D10*100000/12 -> 7500000

Sheet Income Statement
C3: Income Statement (Monthly)
C6: Particulars | D6: ₹ / Unit | E6: Per Month
C7: Selling Price | D7: 1000 | E7: =D7*100000/12 -> 8333333.3
C8: Total Cost | D8: 900 | E8: =D8*100000/12 -> 7500000
C9: Operating Profit | D9: 100 | E9: =D9*100000/12 -> 833333.33
C10: Operating Margin | D10: 0.1
C13: *Base FX Rate @ ₹87

Sheet Per Unit & Monthly FX Impact
D3: Exchange Rate to Profit Base
C5: Date | D5: Forecast(USD_INR) | E5: Base USD Cost Of Import | F5: Cost Of Import (In Rupees) | G5: Monthly Import cost | H5: Base Import Cost | I5: Changes in Per unit cost | J5: Total Cost | K5: Total Monthly Cost | L5: Proft | M5: Profit Margin | N5: Monthly Profit | O5: Base monthly Profit | P5: FX Impact | Q5: FX Impact %
C6: Jan-2026 | D6: 93.728234 | E6: 3.4482759 | F6: =D6*E6 -> 323.20081 | G6: =F6*100000/12 -> 2693340.1 | H6: 300 | I6: =F6-H6 -> 23.200808 | J6: =600+F6 -> 923.20081 | K6: =J6*100000/12 -> 7693340.1 | L6: =1000-J6 -> 76.799192 | M6: =L6/J6*100 -> 8.318796 | N6: =(L6*100000)/12 -> 639993.27 | O6: 833333.33 | P6: =N6-O6 -> -193340.07 | Q6: =P6/O6*100 -> -23.200808
C7: Feb-2026 | D7: 95.227098 | E7: 3.4482759 | F7: =D7*E7 -> 328.3693 | G7: =F7*100000/12 -> 2736410.9 | H7: 300 | I7: =F7-H7 -> 28.369304 | J7: =600+F7 -> 928.3693 | K7: =J7*100000/12 -> 7736410.9 | L7: =1000-J7 -> 71.630696 | M7: =L7/J7*100 -> 7.7157545 | N7: =L7*100000/12 -> 596922.47 | O7: 833333.33 | P7: =N7-O7 -> -236410.87 | Q7: =P7/O7*100 -> -28.369304
C8: Mar-2026 | D8: 94.128125 | E8: 3.4482759 | F8: =D8*E8 -> 324.57974 | G8: =F8*100000/12 -> 2704831.2 | H8: 300 | I8: =F8-H8 -> 24.579742 | J8: =600+F8 -> 924.57974 | K8: =J8*100000/12 -> 7704831.2 | L8: =1000-J8 -> 75.420258 | M8: =L8/J8*100 -> 8.1572475 | N8: =L8*100000/12 -> 628502.15 | O8: 833333.33 | P8: =N8-O8 -> -204831.19 | Q8: =P8/O8*100 -> -24.579742
C9: Apr-2026 | D9: 92.947736 | E9: 3.4482759 | F9: =D9*E9 -> 320.50944 | G9: =F9*100000/12 -> 2670912 | H9: 300 | I9: =F9-H9 -> 20.509435 | J9: =600+F9 -> 920.50944 | K9: =J9*100000/12 -> 7670912 | L9: =1000-J9 -> 79.490565 | M9: =L9/J9*100 -> 8.635497 | N9: =L9*100000/12 -> 662421.37 | O9: 833333.33 | P9: =N9-O9 -> -170911.96 | Q9: =P9/O9*100 -> -20.509435
C10: May-2026 | D10: 92.907177 | E10: 3.4482759 | F10: =D10*E10 -> 320.36958 | G10: =F10*100000/12 -> 2669746.5 | H10: 300 | I10: =F10-H10 -> 20.369575 | J10: =600+F10 -> 920.36958 | K10: =J10*100000/12 -> 7669746.5 | L10: =1000-J10 -> 79.630425 | M10: =L10/J10*100 -> 8.6520053 | N10: =L10*100000/12 -> 663586.87 | O10: 833333.33 | P10: =N10-O10 -> -169746.46 | Q10: =P10/O10*100 -> -20.369575
C11: Jun-2026 | D11: 93.380338 | E11: 3.4482759 | F11: =D11*E11 -> 322.00116 | G11: =F11*100000/12 -> 2683343 | H11: 300 | I11: =F11-H11 -> 22.001165 | J11: =600+F11 -> 922.00116 | K11: =J11*100000/12 -> 7683343 | L11: =1000-J11 -> 77.998835 | M11: =L11/J11*100 -> 8.4597328 | N11: =L11*100000/12 -> 649990.29 | O11: 833333.33 | P11: =N11-O11 -> -183343.04 | Q11: =P11/O11*100 -> -22.001165
C12: Jul-2026 | D12: 91.742824 | E12: 3.4482759 | F12: =D12*E12 -> 316.35457 | G12: =F12*100000/12 -> 2636288 | H12: 300 | I12: =F12-H12 -> 16.354566 | J12: =600+F12 -> 916.35457 | K12: =J12*100000/12 -> 7636288 | L12: =1000-J12 -> 83.645434 | M12: =L12/J12*100 -> 9.1280643 | N12: =L12*100000/12 -> 697045.28 | O12: 833333.33 | P12: =N12-O12 -> -136288.05 | Q12: =P12/O12*100 -> -16.354566
C13: Aug-2026 | D13: 91.70021 | E13: 3.4482759 | F13: =D13*E13 -> 316.20762 | G13: =F13*100000/12 -> 2635063.5 | H13: 300 | I13: =F13-H13 -> 16.207621 | J13: =600+F13 -> 916.20762 | K13: =J13*100000/12 -> 7635063.5 | L13: =1000-J13 -> 83.792379 | M13: =L13/J13*100 -> 9.1455667 | N13: =L13*100000/12 -> 698269.82 | O13: 833333.33 | P13: =N13-O13 -> -135063.51 | Q13: =P13/O13*100 -> -16.207621
C14: Sep-2026 | D14: 91.88466 | E14: 3.4482759 | F14: =D14*E14 -> 316.84366 | G14: =F14*100000/12 -> 2640363.8 | H14: 300 | I14: =F14-H14 -> 16.843656 | J14: =600+F14 -> 916.84366 | K14: =J14*100000/12 -> 7640363.8 | L14: =1000-J14 -> 83.156344 | M14: =L14/J14*100 -> 9.06985 | N14: =L14*100000/12 -> 692969.53 | O14: 833333.33 | P14: =N14-O14 -> -140363.8 | Q14: =P14/O14*100 -> -16.843656
C15: Oct-2026 | D15: 91.588021 | E15: 3.4482759 | F15: =D15*E15 -> 315.82076 | G15: =F15*100000/12 -> 2631839.7 | H15: 300 | I15: =F15-H15 -> 15.820762 | J15: =600+F15 -> 915.82076 | K15: =J15*100000/12 -> 7631839.7 | L15: =1000-J15 -> 84.179238 | M15: =L15/J15*100 -> 9.1916718 | N15: =L15*100000/12 -> 701493.65 | O15: 833333.33 | P15: =N15-O15 -> -131839.68 | Q15: =P15/O15*100 -> -15.820762
C16: Nov-2026 | D16: 91.072079 | E16: 3.4482759 | F16: =D16*E16 -> 314.04165 | G16: =F16*100000/12 -> 2617013.8 | H16: 300 | I16: =F16-H16 -> 14.041652 | J16: =600+F16 -> 914.04165 | K16: =J16*100000/12 -> 7617013.8 | L16: =1000-J16 -> 85.958348 | M16: =L16/J16*100 -> 9.4042047 | N16: =L16*100000/12 -> 716319.57 | O16: 833333.33 | P16: =N16-O16 -> -117013.77 | Q16: =P16/O16*100 -> -14.041652
C17: Dec-2026 | D17: 92.965644 | E17: 3.4482759 | F17: =D17*E17 -> 320.57119 | G17: =F17*100000/12 -> 2671426.5 | H17: 300 | I17: =F17-H17 -> 20.571185 | J17: =600+F17 -> 920.57119 | K17: =J17*100000/12 -> 7671426.5 | L17: =1000-J17 -> 79.428815 | M17: =L17/J17*100 -> 8.62821 | N17: =L17*100000/12 -> 661906.79 | O17: 833333.33 | P17: =N17-O17 -> -171426.54 | Q17: =P17/O17*100 -> -20.571185
D20: Exchange Rate to Profit Favourable
C22: Date | D22: Forecast(USD_INR) | E22: Base USD Cost Of Import | F22: Cost Of Import (In Rupees) | G22: Monthly Import cost | H22: Base Import Cost | I22: Changes in Per unit cost | J22: Total Cost | K22: Total Monthly Cost | L22: Proft | M22: Profit Margin | N22: Monthly Profit | O22: Base monthly Profit | P22: FX Impact | Q22: FX Impact %
C23: Jan-2026 | D23: 91.143532 | E23: 3.4482759 | F23: =D23*E23 -> 314.28804 | G23: =F23*100000/12 -> 2619067 | H23: 300 | I23: =F23-H23 -> 14.288042 | J23: =600+F23 -> 914.28804 | K23: =J23*100000/12 -> 7619067 | L23: =1000-J23 -> 85.711958 | M23: =L23/J23*100 -> 9.3747216 | N23: =(L23*100000)/12 -> 714266.32 | O23: 833333.33 | P23: =N23-O23 -> -119067.01 | Q23: =P23/O23*100 -> -14.288042
C24: Feb-2026 | D24: 92.016032 | E24: 3.4482759 | F24: =D24*E24 -> 317.29666 | G24: =F24*100000/12 -> 2644138.9 | H24: 300 | I24: =F24-H24 -> 17.296663 | J24: =600+F24 -> 917.29666 | K24: =J24*100000/12 -> 7644138.9 | L24: =1000-J24 -> 82.703337 | M24: =L24/J24*100 -> 9.0159858 | N24: =L24*100000/12 -> 689194.47 | O24: 833333.33 | P24: =N24-O24 -> -144138.86 | Q24: =P24/O24*100 -> -17.296663
C25: Mar-2026 | D25: 90.310868 | E25: 3.4482759 | F25: =D25*E25 -> 311.41679 | G25: =F25*100000/12 -> 2595139.9 | H25: 300 | I25: =F25-H25 -> 11.416785 | J25: =600+F25 -> 911.41679 | K25: =J25*100000/12 -> 7595139.9 | L25: =1000-J25 -> 88.583215 | M25: =L25/J25*100 -> 9.7192872 | N25: =L25*100000/12 -> 738193.46 | O25: 833333.33 | P25: =N25-O25 -> -95139.878 | Q25: =P25/O25*100 -> -11.416785
C26: Apr-2026 | D26: 88.530425 | E26: 3.4482759 | F26: =D26*E26 -> 305.27733 | G26: =F26*100000/12 -> 2543977.7 | H26: 300 | I26: =F26-H26 -> 5.2773274 | J26: =600+F26 -> 905.27733 | K26: =J26*100000/12 -> 7543977.7 | L26: =1000-J26 -> 94.722673 | M26: =L26/J26*100 -> 10.463387 | N26: =L26*100000/12 -> 789355.61 | O26: 833333.33 | P26: =N26-O26 -> -43977.728 | Q26: =P26/O26*100 -> -5.2773274
C27: May-2026 | D27: 87.888719 | E27: 3.4482759 | F27: =D27*E27 -> 303.06455 | G27: =F27*100000/12 -> 2525537.9 | H27: 300 | I27: =F27-H27 -> 3.0645488 | J27: =600+F27 -> 903.06455 | K27: =J27*100000/12 -> 7525537.9 | L27: =1000-J27 -> 96.935451 | M27: =L27/J27*100 -> 10.734056 | N27: =L27*100000/12 -> 807795.43 | O27: 833333.33 | P27: =N27-O27 -> -25537.906 | Q27: =P27/O27*100 -> -3.0645488
C28: Jun-2026 | D28: 87.755508 | E28: 3.4482759 | F28: =D28*E28 -> 302.6052 | G28: =F28*100000/12 -> 2521710 | H28: 300 | I28: =F28-H28 -> 2.6052002 | J28: =600+F28 -> 902.6052 | K28: =J28*100000/12 -> 7521710 | L28: =1000-J28 -> 97.3948 | M28: =L28/J28*100 -> 10.79041 | N28: =L28*100000/12 -> 811623.33 | O28: 833333.33 | P28: =N28-O28 -> -21710.002 | Q28: =P28/O28*100 -> -2.6052002
C29: Jul-2026 | D29: 85.503879 | E29: 3.4482759 | F29: =D29*E29 -> 294.84096 | G29: =F29*100000/12 -> 2457008 | H29: 300 | I29: =F29-H29 -> -5.1590377 | J29: =600+F29 -> 894.84096 | K29: =J29*100000/12 -> 7457008 | L29: =1000-J29 -> 105.15904 | M29: =L29/J29*100 -> 11.751701 | N29: =L29*100000/12 -> 876325.31 | O29: 833333.33 | P29: =N29-O29 -> 42991.981 | Q29: =P29/O29*100 -> 5.1590377
C30: Aug-2026 | D30: 84.837811 | E30: 3.4482759 | F30: =D30*E30 -> 292.54418 | G30: =F30*100000/12 -> 2437868.1 | H30: 300 | I30: =F30-H30 -> -7.4558226 | J30: =600+F30 -> 892.54418 | K30: =J30*100000/12 -> 7437868.1 | L30: =1000-J30 -> 107.45582 | M30: =L30/J30*100 -> 12.039272 | N30: =L30*100000/12 -> 895465.19 | O30: 833333.33 | P30: =N30-O30 -> 62131.855 | Q30: =P30/O30*100 -> 7.4558226
C31: Sep-2026 | D31: 84.388436 | E31: 3.4482759 | F31: =D31*E31 -> 290.99461 | G31: =F31*100000/12 -> 2424955.1 | H31: 300 | I31: =F31-H31 -> -9.0053915 | J31: =600+F31 -> 890.99461 | K31: =J31*100000/12 -> 7424955.1 | L31: =1000-J31 -> 109.00539 | M31: =L31/J31*100 -> 12.234125 | N31: =L31*100000/12 -> 908378.26 | O31: 833333.33 | P31: =N31-O31 -> 75044.929 | Q31: =P31/O31*100 -> 9.0053915
C32: Oct-2026 | D32: 83.446926 | E32: 3.4482759 | F32: =D32*E32 -> 287.74802 | G32: =F32*100000/12 -> 2397900.2 | H32: 300 | I32: =F32-H32 -> -12.251978 | J32: =600+F32 -> 887.74802 | K32: =J32*100000/12 -> 7397900.2 | L32: =1000-J32 -> 112.25198 | M32: =L32/J32*100 -> 12.644577 | N32: =L32*100000/12 -> 935433.15 | O32: 833333.33 | P32: =N32-O32 -> 102099.82 | Q32: =P32/O32*100 -> 12.251978
C33: Nov-2026 | D33: 82.274631 | E33: 3.4482759 | F33: =D33*E33 -> 283.70563 | G33: =F33*100000/12 -> 2364213.5 | H33: 300 | I33: =F33-H33 -> -16.294374 | J33: =600+F33 -> 883.70563 | K33: =J33*100000/12 -> 7364213.5 | L33: =1000-J33 -> 116.29437 | M33: =L33/J33*100 -> 13.159854 | N33: =L33*100000/12 -> 969119.79 | O33: 833333.33 | P33: =N33-O33 -> 135786.45 | Q33: =P33/O33*100 -> 16.294374
C34: Dec-2026 | D34: 83.500086 | E34: 3.4482759 | F34: =D34*E34 -> 287.93133 | G34: =F34*100000/12 -> 2399427.8 | H34: 300 | I34: =F34-H34 -> -12.06867 | J34: =600+F34 -> 887.93133 | K34: =J34*100000/12 -> 7399427.8 | L34: =1000-J34 -> 112.06867 | M34: =L34/J34*100 -> 12.621322 | N34: =L34*100000/12 -> 933905.58 | O34: 833333.33 | P34: =N34-O34 -> 100572.25 | Q34: =P34/O34*100 -> 12.06867
E37: Exchange Rate to Profit Adverse
C39: Date | D39: Forecast(USD_INR) | E39: Base USD Cost Of Import | F39: Cost Of Import (In Rupees) | G39: Monthly Import cost | H39: Base Import Cost | I39: Changes in Per unit cost | J39: Total Cost | K39: Total Monthly Cost | L39: Proft | M39: Profit Margin | N39: Monthly Profit | O39: Base monthly Profit | P39: FX Impact | Q39: FX Impact %
C40: Jan-2026 | D40: 96.312937 | E40: 3.4482759 | F40: =E40*D40 -> 332.11357 | G40: =F40*100000/12 -> 2767613.1 | H40: 300 | I40: =F40-H40 -> 32.113575 | J40: =600+F40 -> 932.11357 | K40: =J40*100000/12 -> 7767613.1 | L40: =1000-J40 -> 67.886425 | M40: =L40/J40*100 -> 7.2830637 | N40: =(L40*100000)/12 -> 565720.21 | O40: 833333.33 | P40: =N40-O40 -> -267613.12 | Q40: =P40/O40*100 -> -32.113575
C41: Feb-2026 | D41: 98.438164 | E41: 3.4482759 | F41: =E41*D41 -> 339.44194 | G41: =F41*100000/12 -> 2828682.9 | H41: 300 | I41: =F41-H41 -> 39.441945 | J41: =600+F41 -> 939.44194 | K41: =J41*100000/12 -> 7828682.9 | L41: =1000-J41 -> 60.558055 | M41: =L41/J41*100 -> 6.4461732 | N41: =L41*100000/12 -> 504650.46 | O41: 833333.33 | P41: =N41-O41 -> -328682.87 | Q41: =P41/O41*100 -> -39.441945
C42: Mar-2026 | D42: 97.945383 | E42: 3.4482759 | F42: =E42*D42 -> 337.7427 | G42: =F42*100000/12 -> 2814522.5 | H42: 300 | I42: =F42-H42 -> 37.742699 | J42: =600+F42 -> 937.7427 | K42: =J42*100000/12 -> 7814522.5 | L42: =1000-J42 -> 62.257301 | M42: =L42/J42*100 -> 6.63906 | N42: =L42*100000/12 -> 518810.84 | O42: 833333.33 | P42: =N42-O42 -> -314522.49 | Q42: =P42/O42*100 -> -37.742699
C43: Apr-2026 | D43: 97.365048 | E43: 3.4482759 | F43: =E43*D43 -> 335.74154 | G43: =F43*100000/12 -> 2797846.2 | H43: 300 | I43: =F43-H43 -> 35.741544 | J43: =600+F43 -> 935.74154 | K43: =J43*100000/12 -> 7797846.2 | L43: =1000-J43 -> 64.258456 | M43: =L43/J43*100 -> 6.8671159 | N43: =L43*100000/12 -> 535487.14 | O43: 833333.33 | P43: =N43-O43 -> -297846.2 | Q43: =P43/O43*100 -> -35.741544
C44: May-2026 | D44: 97.925635 | E44: 3.4482759 | F44: =E44*D44 -> 337.6746 | G44: =F44*100000/12 -> 2813955 | H44: 300 | I44: =F44-H44 -> 37.674602 | J44: =600+F44 -> 937.6746 | K44: =J44*100000/12 -> 7813955 | L44: =1000-J44 -> 62.325398 | M44: =L44/J44*100 -> 6.6468046 | N44: =L44*100000/12 -> 519378.32 | O44: 833333.33 | P44: =N44-O44 -> -313955.01 | Q44: =P44/O44*100 -> -37.674602
C45: Jun-2026 | D45: 99.005168 | E45: 3.4482759 | F45: =E45*D45 -> 341.39713 | G45: =F45*100000/12 -> 2844976.1 | H45: 300 | I45: =F45-H45 -> 41.397129 | J45: =600+F45 -> 941.39713 | K45: =J45*100000/12 -> 7844976.1 | L45: =1000-J45 -> 58.602871 | M45: =L45/J45*100 -> 6.2250955 | N45: =L45*100000/12 -> 488357.26 | O45: 833333.33 | P45: =N45-O45 -> -344976.08 | Q45: =P45/O45*100 -> -41.397129
C46: Jul-2026 | D46: 97.981769 | E46: 3.4482759 | F46: =E46*D46 -> 337.86817 | G46: =F46*100000/12 -> 2815568.1 | H46: 300 | I46: =F46-H46 -> 37.86817 | J46: =600+F46 -> 937.86817 | K46: =J46*100000/12 -> 7815568.1 | L46: =1000-J46 -> 62.13183 | M46: =L46/J46*100 -> 6.6247936 | N46: =L46*100000/12 -> 517765.25 | O46: 833333.33 | P46: =N46-O46 -> -315568.08 | Q46: =P46/O46*100 -> -37.86817
C47: Aug-2026 | D47: 98.562609 | E47: 3.4482759 | F47: =E47*D47 -> 339.87107 | G47: =F47*100000/12 -> 2832258.9 | H47: 300 | I47: =F47-H47 -> 39.871065 | J47: =600+F47 -> 939.87107 | K47: =J47*100000/12 -> 7832258.9 | L47: =1000-J47 -> 60.128935 | M47: =L47/J47*100 -> 6.3975727 | N47: =L47*100000/12 -> 501074.46 | O47: 833333.33 | P47: =N47-O47 -> -332258.88 | Q47: =P47/O47*100 -> -39.871065
C48: Sep-2026 | D48: 99.380884 | E48: 3.4482759 | F48: =E48*D48 -> 342.6927 | G48: =F48*100000/12 -> 2855772.5 | H48: 300 | I48: =F48-H48 -> 42.692704 | J48: =600+F48 -> 942.6927 | K48: =J48*100000/12 -> 7855772.5 | L48: =1000-J48 -> 57.307296 | M48: =L48/J48*100 -> 6.0791068 | N48: =L48*100000/12 -> 477560.8 | O48: 833333.33 | P48: =N48-O48 -> -355772.53 | Q48: =P48/O48*100 -> -42.692704
C49: Oct-2026 | D49: 99.729115 | E49: 3.4482759 | F49: =E49*D49 -> 343.8935 | G49: =F49*100000/12 -> 2865779.2 | H49: 300 | I49: =F49-H49 -> 43.893501 | J49: =600+F49 -> 943.8935 | K49: =J49*100000/12 -> 7865779.2 | L49: =1000-J49 -> 56.106499 | M49: =L49/J49*100 -> 5.9441556 | N49: =L49*100000/12 -> 467554.15 | O49: 833333.33 | P49: =N49-O49 -> -365779.18 | Q49: =P49/O49*100 -> -43.893501
...

Sheet Quarterly FX Impact
C3: Exchange Rate to Profit Base
B5: Quarters | C5: Base Profit | D5: Actual Profit | E5: FX Impact | F5: FX Impact % | H5: Worst Quarter Loss in ₹ | K5: =MIN(E6:E9) -> -634582.12
B6: 1 | C6: 2500000 | D6: =SUM('Per Unit & Monthly FX Impact'!N6:N8) -> 1865417.9 | E6: =D6-C6 -> -634582.12 | F6: =E6/C6 -> -0.25383285 | H6: Worst Quarter Loss in % | K6: =MIN(F6:F9) -> -0.25383285
B7: 2 | C7: 2500000 | D7: =SUM('Per Unit & Monthly FX Impact'!N9:N11) -> 1975998.5 | E7: =D7-C7 -> -524001.46 | F7: =E7/C7 -> -0.20960058 | H7: Average FX Impact in ₹ | K7: =AVERAGE(E6:E9) -> -497644.73
B8: 3 | C8: 2500000 | D8: =SUM('Per Unit & Monthly FX Impact'!N12:N14) -> 2088284.6 | E8: =D8-C8 -> -411715.36 | F8: =E8/C8 -> -0.16468614 | H8: Average FX Impact in % | K8: =AVERAGE(F6:F9) -> -0.19905789
B9: 4 | C9: 2500000 | D9: =SUM('Per Unit & Monthly FX Impact'!N15:N17) -> 2079720 | E9: =D9-C9 -> -420279.99 | F9: =E9/C9 -> -0.168112 | H9: Volatility Under FX | K9: =MAX(E6:E9)-MIN(E6:E9) -> 222866.76
C12: Exchange Rate to Profit Favourable
B14: Quarters | C14: Base Profit | D14: Actual Profit | E14: FX Impact | F14: FX Impact % | H14: Worst Quarter Loss in ₹ | K14: =MIN(E15:E18) -> -358345.75 | O14: S
B15: 1 | C15: 2500000 | D15: =SUM('Per Unit & Monthly FX Impact'!N23:N25) -> 2141654.3 | E15: =D15-C15 -> -358345.75 | F15: =E15/C15 -> -0.1433383 | H15: Worst Quarter Loss in % | K15: =MIN(F15:F18) -> -0.1433383
B16: 2 | C16: 2500000 | D16: =SUM('Per Unit & Monthly FX Impact'!N26:N28) -> 2408774.4 | E16: =D16-C16 -> -91225.636 | F16: =E16/C16 -> -0.036490254 | H16: Average FX Impact in ₹ | K16: =AVERAGE(E15:E18) -> 17263.975
B17: 3 | C17: 2500000 | D17: =SUM('Per Unit & Monthly FX Impact'!N29:N31) -> 2680168.8 | E17: =D17-C17 -> 180168.77 | F17: =E17/C17 -> 0.072067506 | H17: Average FX Impact in % | K17: =AVERAGE(F15:F18) -> 0.0069055901
B18: 4 | C18: 2500000 | D18: =SUM('Per Unit & Monthly FX Impact'!N32:N34) -> 2838458.5 | E18: =D18-C18 -> 338458.52 | F18: =E18/C18 -> 0.13538341 | H18: Volatility Under FX | K18: =MAX(E15:E18)-MIN(E15:E18) -> 696804.27
C20: Exchange Rate to Profit Adverse
B22: Quarters | C22: Base Profit | D22: Actual Profit | E22: FX Impact | F22: FX Impact % | H22: Worst Quarter Loss in ₹ | K22: =MIN(E23:E26) -> -1179018.5
B23: 1 | C23: 2500000 | D23: =SUM('Per Unit & Monthly FX Impact'!N40:N42) -> 1589181.5 | E23: =D23-C23 -> -910818.49 | F23: =E23/C23 -> -0.3643274 | H23: Worst Quarter Loss in % | K23: =MIN(F23:F26) -> -0.4716074
B24: 2 | C24: 2500000 | D24: =SUM('Per Unit & Monthly FX Impact'!N43:N45) -> 1543222.7 | E24: =D24-C24 -> -956777.29 | F24: =E24/C24 -> -0.38271092 | H24: Average FX Impact in ₹ | K24: =AVERAGE(E23:E26) -> -1012553.4
B25: 3 | C25: 2500000 | D25: =SUM('Per Unit & Monthly FX Impact'!N46:N48) -> 1496400.5 | E25: =D25-C25 -> -1003599.5 | F25: =E25/C25 -> -0.40143979 | H25: Average FX Impact in % | K25: =AVERAGE(F23:F26) -> -0.40502138
B26: 4 | C26: 2500000 | D26: =SUM('Per Unit & Monthly FX Impact'!N49:N51) -> 1320981.5 | E26: =D26-C26 -> -1179018.5 | F26: =E26/C26 -> -0.4716074 | H26: Volatility Under FX | K26: =MAX(E23:E26)-MIN(E23:E26) -> 268200.01

Sheet Per Unit Hedging Impact
C3: Exchange Rate to Profit Base | Q3: Per Unit Hedging Impact @ Base Exchange Rate
B5: Date | C5: Forecast(USD_INR) | D5: Base USD Cost Of Import | E5: Hedging @ 50% | F5: Hedged @ 88 INR | G5: Unhedged Cost (50%) | H5: Total Import Cost | I5: Total Cost | J5: hedged Profit | K5: Hedged Profit Margin | L5: Unhedged Profit | M5: Unhedges Profit Margin | N5: Hedge Impact | Q5: hedged Profit | R5: Unhedged Profit | S5: Hedge Impact
B6: Jan-2026 | C6: 93.728234 | D6: 3.4482759 | E6: =D6*50/100 -> 1.7241379 | F6: =E6*88 -> 151.72414 | G6: =E6*C6 -> 161.6004 | H6: =F6+G6 -> 313.32454 | I6: =H6+600 -> 913.32454 | J6: =1000-I6 -> 86.675458 | K6: =J6/1000*100 -> 8.6675458 | L6: 76.799192 | M6: 8.318796 | N6: =J6-L6 -> 9.8762661 | Q6: 86.675458 | R6: 76.799192 | S6: 9.8762661
B7: Feb-2026 | C7: 95.227098 | D7: 3.4482759 | E7: =D7*50/100 -> 1.7241379 | F7: =E7*88 -> 151.72414 | G7: =E7*C7 -> 164.18465 | H7: =F7+G7 -> 315.90879 | I7: =H7+600 -> 915.90879 | J7: =1000-I7 -> 84.09121 | K7: =J7/1000*100 -> 8.409121 | L7: 71.630696 | M7: 7.7157545 | N7: =J7-L7 -> 12.460514 | Q7: 84.09121 | R7: 71.630696 | S7: 12.460514
B8: Mar-2026 | C8: 94.128125 | D8: 3.4482759 | E8: =D8*50/100 -> 1.7241379 | F8: =E8*88 -> 151.72414 | G8: =E8*C8 -> 162.28987 | H8: =F8+G8 -> 314.01401 | I8: =H8+600 -> 914.01401 | J8: =1000-I8 -> 85.985991 | K8: =J8/1000*100 -> 8.5985991 | L8: 75.420258 | M8: 8.1572475 | N8: =J8-L8 -> 10.565733 | Q8: 85.985991 | R8: 75.420258 | S8: 10.565733
B9: Apr-2026 | C9: 92.947736 | D9: 3.4482759 | E9: =D9*50/100 -> 1.7241379 | F9: =E9*88 -> 151.72414 | G9: =E9*C9 -> 160.25472 | H9: =F9+G9 -> 311.97886 | I9: =H9+600 -> 911.97886 | J9: =1000-I9 -> 88.021144 | K9: =J9/1000*100 -> 8.8021144 | L9: 79.490565 | M9: 8.635497 | N9: =J9-L9 -> 8.5305798 | Q9: 88.021144 | R9: 79.490565 | S9: 8.5305798
B10: May-2026 | C10: 92.907177 | D10: 3.4482759 | E10: =D10*50/100 -> 1.7241379 | F10: =E10*88 -> 151.72414 | G10: =E10*C10 -> 160.18479 | H10: =F10+G10 -> 311.90893 | I10: =H10+600 -> 911.90893 | J10: =1000-I10 -> 88.091074 | K10: =J10/1000*100 -> 8.8091074 | L10: 79.630425 | M10: 8.6520053 | N10: =J10-L10 -> 8.4606497 | Q10: 88.091074 | R10: 79.630425 | S10: 8.4606497
B11: Jun-2026 | C11: 93.380338 | D11: 3.4482759 | E11: =D11*50/100 -> 1.7241379 | F11: =E11*88 -> 151.72414 | G11: =E11*C11 -> 161.00058 | H11: =F11+G11 -> 312.72472 | I11: =H11+600 -> 912.72472 | J11: =1000-I11 -> 87.27528 | K11: =J11/1000*100 -> 8.727528 | L11: 77.998835 | M11: 8.4597328 | N11: =J11-L11 -> 9.2764445 | Q11: 87.27528 | R11: 77.998835 | S11: 9.2764445
B12: Jul-2026 | C12: 91.742824 | D12: 3.4482759 | E12: =D12*50/100 -> 1.7241379 | F12: =E12*88 -> 151.72414 | G12: =E12*C12 -> 158.17728 | H12: =F12+G12 -> 309.90142 | I12: =H12+600 -> 909.90142 | J12: =1000-I12 -> 90.098579 | K12: =J12/1000*100 -> 9.0098579 | L12: 83.645434 | M12: 9.1280643 | N12: =J12-L12 -> 6.453145 | Q12: 90.098579 | R12: 83.645434 | S12: 6.453145
B13: Aug-2026 | C13: 91.70021 | D13: 3.4482759 | E13: =D13*50/100 -> 1.7241379 | F13: =E13*88 -> 151.72414 | G13: =E13*C13 -> 158.10381 | H13: =F13+G13 -> 309.82795 | I13: =H13+600 -> 909.82795 | J13: =1000-I13 -> 90.172051 | K13: =J13/1000*100 -> 9.0172051 | L13: 83.792379 | M13: 9.1455667 | N13: =J13-L13 -> 6.3796727 | Q13: 90.172051 | R13: 83.792379 | S13: 6.3796727
B14: Sep-2026 | C14: 91.88466 | D14: 3.4482759 | E14: =D14*50/100 -> 1.7241379 | F14: =E14*88 -> 151.72414 | G14: =E14*C14 -> 158.42183 | H14: =F14+G14 -> 310.14597 | I14: =H14+600 -> 910.14597 | J14: =1000-I14 -> 89.854034 | K14: =J14/1000*100 -> 8.9854034 | L14: 83.156344 | M14: 9.06985 | N14: =J14-L14 -> 6.6976901 | Q14: 89.854034 | R14: 83.156344 | S14: 6.6976901
B15: Oct-2026 | C15: 91.588021 | D15: 3.4482759 | E15: =D15*50/100 -> 1.7241379 | F15: =E15*88 -> 151.72414 | G15: =E15*C15 -> 157.91038 | H15: =F15+G15 -> 309.63452 | I15: =H15+600 -> 909.63452 | J15: =1000-I15 -> 90.365481 | K15: =J15/1000*100 -> 9.0365481 | L15: 84.179238 | M15: 9.1916718 | N15: =J15-L15 -> 6.1862428 | Q15: 90.365481 | R15: 84.179238 | S15: 6.1862428
B16: Nov-2026 | C16: 91.072079 | D16: 3.4482759 | E16: =D16*50/100 -> 1.7241379 | F16: =E16*88 -> 151.72414 | G16: =E16*C16 -> 157.02083 | H16: =F16+G16 -> 308.74496 | I16: =H16+600 -> 908.74496 | J16: =1000-I16 -> 91.255036 | K16: =J16/1000*100 -> 9.1255036 | L16: 85.958348 | M16: 9.4042047 | N16: =J16-L16 -> 5.2966882 | Q16: 91.255036 | R16: 85.958348 | S16: 5.2966882
B17: Dec-2026 | C17: 92.965644 | D17: 3.4482759 | E17: =D17*50/100 -> 1.7241379 | F17: =E17*88 -> 151.72414 | G17: =E17*C17 -> 160.28559 | H17: =F17+G17 -> 312.00973 | I17: =H17+600 -> 912.00973 | J17: =1000-I17 -> 87.99027 | K17: =J17/1000*100 -> 8.799027 | L17: 79.428815 | M17: 8.62821 | N17: =J17-L17 -> 8.5614546 | Q17: 87.99027 | R17: 79.428815 | S17: 8.5614546
C20: Exchange Rate to Profit Favourable | Q20: Per Unit Hedging Impact @ Favourable Exchange Rate
B22: Date | C22: Forecast(USD_INR) | D22: Base USD Cost Of Import | E22: Hedging @ 50% | F22: Hedged @ 88 INR | G22: Unhedged Cost (50%) | H22: Total Import Cost | I22: Total Cost | J22: hedged Profit | K22: Hedged Profit Margin | L22: Unhedged Profit | M22: Unhedges Profit Margin | N22: Hedge Impact | Q22: hedged Profit | R22: Unhedged Profit | S22: Hedge Impact
B23: Jan-2026 | C23: 91.143532 | D23: 3.4482759 | E23: =D23*50/100 -> 1.7241379 | F23: =E23*88 -> 151.72414 | G23: =E23*C23 -> 157.14402 | H23: =F23+G23 -> 308.86816 | I23: =H23+600 -> 908.86816 | J23: =1000-I23 -> 91.131841 | K23: =J23/1000*100 -> 9.1131841 | L23: 85.711958 | M23: 9.3747216 | N23: =J23-L23 -> 5.4198828 | Q23: 91.131841 | R23: 85.711958 | S23: 5.4198828
B24: Feb-2026 | C24: 92.016032 | D24: 3.4482759 | E24: =D24*50/100 -> 1.7241379 | F24: =E24*88 -> 151.72414 | G24: =E24*C24 -> 158.64833 | H24: =F24+G24 -> 310.37247 | I24: =H24+600 -> 910.37247 | J24: =1000-I24 -> 89.627531 | K24: =J24/1000*100 -> 8.9627531 | L24: 82.703337 | M24: 9.0159858 | N24: =J24-L24 -> 6.9241936 | Q24: 89.627531 | R24: 82.703337 | S24: 6.9241936
B25: Mar-2026 | C25: 90.310868 | D25: 3.4482759 | E25: =D25*50/100 -> 1.7241379 | F25: =E25*88 -> 151.72414 | G25: =E25*C25 -> 155.70839 | H25: =F25+G25 -> 307.43253 | I25: =H25+600 -> 907.43253 | J25: =1000-I25 -> 92.567469 | K25: =J25/1000*100 -> 9.2567469 | L25: 88.583215 | M25: 9.7192872 | N25: =J25-L25 -> 3.9842547 | Q25: 92.567469 | R25: 88.583215 | S25: 3.9842547
B26: Apr-2026 | C26: 88.530425 | D26: 3.4482759 | E26: =D26*50/100 -> 1.7241379 | F26: =E26*88 -> 151.72414 | G26: =E26*C26 -> 152.63866 | H26: =F26+G26 -> 304.3628 | I26: =H26+600 -> 904.3628 | J26: =1000-I26 -> 95.637198 | K26: =J26/1000*100 -> 9.5637198 | L26: 94.722673 | M26: 10.463387 | N26: =J26-L26 -> 0.91452575 | Q26: 95.637198 | R26: 94.722673 | S26: 0.91452575
B27: May-2026 | C27: 87.888719 | D27: 3.4482759 | E27: =D27*50/100 -> 1.7241379 | F27: =E27*88 -> 151.72414 | G27: =E27*C27 -> 151.53227 | H27: =F27+G27 -> 303.25641 | I27: =H27+600 -> 903.25641 | J27: =1000-I27 -> 96.743588 | K27: =J27/1000*100 -> 9.6743588 | L27: 96.935451 | M27: 10.734056 | N27: =J27-L27 -> -0.19186355 | Q27: 96.743588 | R27: 96.935451 | S27: -0.19186355
B28: Jun-2026 | C28: 87.755508 | D28: 3.4482759 | E28: =D28*50/100 -> 1.7241379 | F28: =E28*88 -> 151.72414 | G28: =E28*C28 -> 151.3026 | H28: =F28+G28 -> 303.02674 | I28: =H28+600 -> 903.02674 | J28: =1000-I28 -> 96.973262 | K28: =J28/1000*100 -> 9.6973262 | L28: 97.3948 | M28: 10.79041 | N28: =J28-L28 -> -0.42153783 | Q28: 96.973262 | R28: 97.3948 | S28: -0.42153783
B29: Jul-2026 | C29: 85.503879 | D29: 3.4482759 | E29: =D29*50/100 -> 1.7241379 | F29: =E29*88 -> 151.72414 | G29: =E29*C29 -> 147.42048 | H29: =F29+G29 -> 299.14462 | I29: =H29+600 -> 899.14462 | J29: =1000-I29 -> 100.85538 | K29: =J29/1000*100 -> 10.085538 | L29: 105.15904 | M29: 11.751701 | N29: =J29-L29 -> -4.3036568 | Q29: 100.85538 | R29: 105.15904 | S29: -4.3036568
B30: Aug-2026 | C30: 84.837811 | D30: 3.4482759 | E30: =D30*50/100 -> 1.7241379 | F30: =E30*88 -> 151.72414 | G30: =E30*C30 -> 146.27209 | H30: =F30+G30 -> 297.99623 | I30: =H30+600 -> 897.99623 | J30: =1000-I30 -> 102.00377 | K30: =J30/1000*100 -> 10.200377 | L30: 107.45582 | M30: 12.039272 | N30: =J30-L30 -> -5.4520492 | Q30: 102.00377 | R30: 107.45582 | S30: -5.4520492
B31: Sep-2026 | C31: 84.388436 | D31: 3.4482759 | E31: =D31*50/100 -> 1.7241379 | F31: =E31*88 -> 151.72414 | G31: =E31*C31 -> 145.4973 | H31: =F31+G31 -> 297.22144 | I31: =H31+600 -> 897.22144 | J31: =1000-I31 -> 102.77856 | K31: =J31/1000*100 -> 10.277856 | L31: 109.00539 | M31: 12.234125 | N31: =J31-L31 -> -6.2268337 | Q31: 102.77856 | R31: 109.00539 | S31: -6.2268337
B32: Oct-2026 | C32: 83.446926 | D32: 3.4482759 | E32: =D32*50/100 -> 1.7241379 | F32: =E32*88 -> 151.72414 | G32: =E32*C32 -> 143.87401 | H32: =F32+G32 -> 295.59815 | I32: =H32+600 -> 895.59815 | J32: =1000-I32 -> 104.40185 | K32: =J32/1000*100 -> 10.440185 | L32: 112.25198 | M32: 12.644577 | N32: =J32-L32 -> -7.8501271 | Q32: 104.40185 | R32: 112.25198 | S32: -7.8501271
B33: Nov-2026 | C33: 82.274631 | D33: 3.4482759 | E33: =D33*50/100 -> 1.7241379 | F33: =E33*88 -> 151.72414 | G33: =E33*C33 -> 141.85281 | H33: =F33+G33 -> 293.57695 | I33: =H33+600 -> 893.57695 | J33: =1000-I33 -> 106.42305 | K33: =J33/1000*100 -> 10.642305 | L33: 116.29437 | M33: 13.159854 | N33: =J33-L33 -> -9.8713251 | Q33: 106.42305 | R33: 116.29437 | S33: -9.8713251
B34: Dec-2026 | C34: 83.500086 | D34: 3.4482759 | E34: =D34*50/100 -> 1.7241379 | F34: =E34*88 -> 151.72414 | G34: =E34*C34 -> 143.96567 | H34: =F34+G34 -> 295.6898 | I34: =H34+600 -> 895.6898 | J34: =1000-I34 -> 104.3102 | K34: =J34/1000*100 -> 10.43102 | L34: 112.06867 | M34: 12.621322 | N34: =J34-L34 -> -7.7584728 | Q34: 104.3102 | R34: 112.06867 | S34: -7.7584728
C37: Exchange Rate to Profit Adverse | Q37: Per Unit Hedging Impact @ Adverse Exchange Rate
B39: Date | C39: Forecast(USD_INR) | D39: Base USD Cost Of Import | E39: Hedging @ 50% | F39: Hedged @ 88 INR | G39: Unhedged Cost (50%) | H39: Total Import Cost | I39: Total Cost | J39: hedged Profit | K39: Hedged Profit Margin | L39: Unhedged Profit | M39: Unhedges Profit Margin | N39: Hedge Impact | Q39: hedged Profit | R39: Unhedged Profit | S39: Hedge Impact
B40: Jan-2026 | C40: 96.312937 | D40: 3.4482759 | E40: =D40*50/100 -> 1.7241379 | F40: =E40*88 -> 151.72414 | G40: =E40*C40 -> 166.05679 | H40: =F40+G40 -> 317.78093 | I40: =H40+600 -> 917.78093 | J40: =1000-I40 -> 82.219075 | K40: =J40/1000*100 -> 8.2219075 | L40: 67.886425 | M40: 7.2830637 | N40: =J40-L40 -> 14.332649 | Q40: 82.219075 | R40: 67.886425 | S40: 14.332649
B41: Feb-2026 | C41: 98.438164 | D41: 3.4482759 | E41: =D41*50/100 -> 1.7241379 | F41: =E41*88 -> 151.72414 | G41: =E41*C41 -> 169.72097 | H41: =F41+G41 -> 321.44511 | I41: =H41+600 -> 921.44511 | J41: =1000-I41 -> 78.55489 | K41: =J41/1000*100 -> 7.855489 | L41: 60.558055 | M41: 6.4461732 | N41: =J41-L41 -> 17.996835 | Q41: 78.55489 | R41: 60.558055 | S41: 17.996835
B42: Mar-2026 | C42: 97.945383 | D42: 3.4482759 | E42: =D42*50/100 -> 1.7241379 | F42: =E42*88 -> 151.72414 | G42: =E42*C42 -> 168.87135 | H42: =F42+G42 -> 320.59549 | I42: =H42+600 -> 920.59549 | J42: =1000-I42 -> 79.404512 | K42: =J42/1000*100 -> 7.9404512 | L42: 62.257301 | M42: 6.63906 | N42: =J42-L42 -> 17.147212 | Q42: 79.404512 | R42: 62.257301 | S42: 17.147212
B43: Apr-2026 | C43: 97.365048 | D43: 3.4482759 | E43: =D43*50/100 -> 1.7241379 | F43: =E43*88 -> 151.72414 | G43: =E43*C43 -> 167.87077 | H43: =F43+G43 -> 319.59491 | I43: =H43+600 -> 919.59491 | J43: =1000-I43 -> 80.40509 | K43: =J43/1000*100 -> 8.040509 | L43: 64.258456 | M43: 6.8671159 | N43: =J43-L43 -> 16.146634 | Q43: 80.40509 | R43: 64.258456 | S43: 16.146634
B44: May-2026 | C44: 97.925635 | D44: 3.4482759 | E44: =D44*50/100 -> 1.7241379 | F44: =E44*88 -> 151.72414 | G44: =E44*C44 -> 168.8373 | H44: =F44+G44 -> 320.56144 | I44: =H44+600 -> 920.56144 | J44: =1000-I44 -> 79.438561 | K44: =J44/1000*100 -> 7.9438561 | L44: 62.325398 | M44: 6.6468046 | N44: =J44-L44 -> 17.113163 | Q44: 79.438561 | R44: 62.325398 | S44: 17.113163
B45: Jun-2026 | C45: 99.005168 | D45: 3.4482759 | E45: =D45*50/100 -> 1.7241379 | F45: =E45*88 -> 151.72414 | G45: =E45*C45 -> 170.69856 | H45: =F45+G45 -> 322.4227 | I45: =H45+600 -> 922.4227 | J45: =1000-I45 -> 77.577297 | K45: =J45/1000*100 -> 7.7577297 | L45: 58.602871 | M45: 6.2250955 | N45: =J45-L45 -> 18.974427 | Q45: 77.577297 | R45: 58.602871 | S45: 18.974427
B46: Jul-2026 | C46: 97.981769 | D46: 3.4482759 | E46: =D46*50/100 -> 1.7241379 | F46: =E46*88 -> 151.72414 | G46: =E46*C46 -> 168.93408 | H46: =F46+G46 -> 320.65822 | I46: =H46+600 -> 920.65822 | J46: =1000-I46 -> 79.341777 | K46: =J46/1000*100 -> 7.9341777 | L46: 62.13183 | M46: 6.6247936 | N46: =J46-L46 -> 17.209947 | Q46: 79.341777 | R46: 62.13183 | S46: 17.209947
B47: Aug-2026 | C47: 98.562609 | D47: 3.4482759 | E47: =D47*50/100 -> 1.7241379 | F47: =E47*88 -> 151.72414 | G47: =E47*C47 -> 169.93553 | H47: =F47+G47 -> 321.65967 | I47: =H47+600 -> 921.65967 | J47: =1000-I47 -> 78.34033 | K47: =J47/1000*100 -> 7.834033 | L47: 60.128935 | M47: 6.3975727 | N47: =J47-L47 -> 18.211395 | Q47: 78.34033 | R47: 60.128935 | S47: 18.211395
B48: Sep-2026 | C48: 99.380884 | D48: 3.4482759 | E48: =D48*50/100 -> 1.7241379 | F48: =E48*88 -> 151.72414 | G48: =E48*C48 -> 171.34635 | H48: =F48+G48 -> 323.07049 | I48: =H48+600 -> 923.07049 | J48: =1000-I48 -> 76.92951 | K48: =J48/1000*100 -> 7.692951 | L48: 57.307296 | M48: 6.0791068 | N48: =J48-L48 -> 19.622214 | Q48: 76.92951 | R48: 57.307296 | S48: 19.622214
B49: Oct-2026 | C49: 99.729115 | D49: 3.4482759 | E49: =D49*50/100 -> 1.7241379 | F49: =E49*88 -> 151.72414 | G49: =E49*C49 -> 171.94675 | H49: =F49+G49 -> 323.67089 | I49: =H49+600 -> 923.67089 | J49: =1000-I49 -> 76.329111 | K49: =J49/1000*100 -> 7.6329111 | L49: 56.106499 | M49: 5.9441556 | N49: =J49-L49 -> 20.222613 | Q49: 76.329111 | R49: 56.106499 | S49: 20.222613
...

Sheet Monthly Hedging Impact
D2: Exchange Rate to Profit Base | M2: Monthly Hedging Impact @ Base Exchange Rate
B4: Date | C4: Base monthly Profit | D4: hedged Profit | E4: Hedged Monthly Profit | F4: UnHedged Profit | G4: UnHedged Monthly Profit | H4: Monthly Hedging Impact | L4: Date | M4: Hedged Monthly Profit | N4: UnHedged Monthly Profit | O4: Hedging Impact
B5: Jan-2026 | C5: 833333.33 | D5: 86.675458 | E5: =D5*100000/12 -> 722295.48 | F5: 76.799192 | G5: 639993.27 | H5: =E5-G5 -> 82302.218 | L5: Jan-2026 | M5: 722295.48 | N5: 639993.27 | O5: 82302.218
B6: Feb-2026 | C6: 833333.33 | D6: 84.09121 | E6: =D6*100000/12 -> 700760.08 | F6: 71.630696 | G6: 596922.47 | H6: =E6-G6 -> 103837.62 | L6: Feb-2026 | M6: 700760.08 | N6: 596922.47 | O6: 103837.62
B7: Mar-2026 | C7: 833333.33 | D7: 85.985991 | E7: =D7*100000/12 -> 716549.92 | F7: 75.420258 | G7: 628502.15 | H7: =E7-G7 -> 88047.777 | L7: Mar-2026 | M7: 716549.92 | N7: 628502.15 | O7: 88047.777
B8: Apr-2026 | C8: 833333.33 | D8: 88.021144 | E8: =D8*100000/12 -> 733509.54 | F8: 79.490565 | G8: 662421.37 | H8: =E8-G8 -> 71088.165 | L8: Apr-2026 | M8: 733509.54 | N8: 662421.37 | O8: 71088.165
B9: May-2026 | C9: 833333.33 | D9: 88.091074 | E9: =D9*100000/12 -> 734092.29 | F9: 79.630425 | G9: 663586.87 | H9: =E9-G9 -> 70505.414 | L9: May-2026 | M9: 734092.29 | N9: 663586.87 | O9: 70505.414
B10: Jun-2026 | C10: 833333.33 | D10: 87.27528 | E10: =D10*100000/12 -> 727294 | F10: 77.998835 | G10: 649990.29 | H10: =E10-G10 -> 77303.704 | L10: Jun-2026 | M10: 727294 | N10: 649990.29 | O10: 77303.704
B11: Jul-2026 | C11: 833333.33 | D11: 90.098579 | E11: =D11*100000/12 -> 750821.49 | F11: 83.645434 | G11: 697045.28 | H11: =E11-G11 -> 53776.209 | L11: Jul-2026 | M11: 750821.49 | N11: 697045.28 | O11: 53776.209
B12: Aug-2026 | C12: 833333.33 | D12: 90.172051 | E12: =D12*100000/12 -> 751433.76 | F12: 83.792379 | G12: 698269.82 | H12: =E12-G12 -> 53163.939 | L12: Aug-2026 | M12: 751433.76 | N12: 698269.82 | O12: 53163.939
B13: Sep-2026 | C13: 833333.33 | D13: 89.854034 | E13: =D13*100000/12 -> 748783.62 | F13: 83.156344 | G13: 692969.53 | H13: =E13-G13 -> 55814.084 | L13: Sep-2026 | M13: 748783.62 | N13: 692969.53 | O13: 55814.084
B14: Oct-2026 | C14: 833333.33 | D14: 90.365481 | E14: =D14*100000/12 -> 753045.68 | F14: 84.179238 | G14: 701493.65 | H14: =E14-G14 -> 51552.024 | L14: Oct-2026 | M14: 753045.68 | N14: 701493.65 | O14: 51552.024
B15: Nov-2026 | C15: 833333.33 | D15: 91.255036 | E15: =D15*100000/12 -> 760458.63 | F15: 85.958348 | G15: 716319.57 | H15: =E15-G15 -> 44139.068 | L15: Nov-2026 | M15: 760458.63 | N15: 716319.57 | O15: 44139.068
B16: Dec-2026 | C16: 833333.33 | D16: 87.99027 | E16: =D16*100000/12 -> 733252.25 | F16: 79.428815 | G16: 661906.79 | H16: =E16-G16 -> 71345.455 | L16: Dec-2026 | M16: 733252.25 | N16: 661906.79 | O16: 71345.455
D19: Exchange Rate to Profit Favourable | M19: Monthly Hedging Impact @ Favourable Exchange Rate
B21: Date | C21: Base monthly Profit | D21: hedged Profit | E21: Hedged Monthly Profit | F21: UnHedged Profit | G21: UnHedged Monthly Profit | H21: Monthly Hedging Impact | L21: Date | M21: Hedged Monthly Profit | N21: UnHedged Monthly Profit | O21: Hedging Impact
B22: Jan-2026 | C22: 833333.33 | D22: 91.131841 | E22: =D22*100000/12 -> 759432.01 | F22: 85.711958 | G22: 714266.32 | H22: =E22-G22 -> 45165.69 | L22: Jan-2026 | M22: 759432.01 | N22: 714266.32 | O22: 45165.69
B23: Feb-2026 | C23: 833333.33 | D23: 89.627531 | E23: =D23*100000/12 -> 746896.09 | F23: 82.703337 | G23: 689194.47 | H23: =E23-G23 -> 57701.614 | L23: Feb-2026 | M23: 746896.09 | N23: 689194.47 | O23: 57701.614
B24: Mar-2026 | C24: 833333.33 | D24: 92.567469 | E24: =D24*100000/12 -> 771395.58 | F24: 88.583215 | G24: 738193.46 | H24: =E24-G24 -> 33202.123 | L24: Mar-2026 | M24: 771395.58 | N24: 738193.46 | O24: 33202.123
B25: Apr-2026 | C25: 833333.33 | D25: 95.637198 | E25: =D25*100000/12 -> 796976.65 | F25: 94.722673 | G25: 789355.61 | H25: =E25-G25 -> 7621.0479 | L25: Apr-2026 | M25: 796976.65 | N25: 789355.61 | O25: 7621.0479
B26: May-2026 | C26: 833333.33 | D26: 96.743588 | E26: =D26*100000/12 -> 806196.56 | F26: 96.935451 | G26: 807795.43 | H26: =E26-G26 -> -1598.8629 | L26: May-2026 | M26: 806196.56 | N26: 807795.43 | O26: -1598.8629
B27: Jun-2026 | C27: 833333.33 | D27: 96.973262 | E27: =D27*100000/12 -> 808110.52 | F27: 97.3948 | G27: 811623.33 | H27: =E27-G27 -> -3512.8153 | L27: Jun-2026 | M27: 808110.52 | N27: 811623.33 | O27: -3512.8153
B28: Jul-2026 | C28: 833333.33 | D28: 100.85538 | E28: =D28*100000/12 -> 840461.51 | F28: 105.15904 | G28: 876325.31 | H28: =E28-G28 -> -35863.807 | L28: Jul-2026 | M28: 840461.51 | N28: 876325.31 | O28: -35863.807
B29: Aug-2026 | C29: 833333.33 | D29: 102.00377 | E29: =D29*100000/12 -> 850031.44 | F29: 107.45582 | G29: 895465.19 | H29: =E29-G29 -> -45433.744 | L29: Aug-2026 | M29: 850031.44 | N29: 895465.19 | O29: -45433.744
B30: Sep-2026 | C30: 833333.33 | D30: 102.77856 | E30: =D30*100000/12 -> 856487.98 | F30: 109.00539 | G30: 908378.26 | H30: =E30-G30 -> -51890.281 | L30: Sep-2026 | M30: 856487.98 | N30: 908378.26 | O30: -51890.281
B31: Oct-2026 | C31: 833333.33 | D31: 104.40185 | E31: =D31*100000/12 -> 870015.43 | F31: 112.25198 | G31: 935433.15 | H31: =E31-G31 -> -65417.726 | L31: Oct-2026 | M31: 870015.43 | N31: 935433.15 | O31: -65417.726
B32: Nov-2026 | C32: 833333.33 | D32: 106.42305 | E32: =D32*100000/12 -> 886858.74 | F32: 116.29437 | G32: 969119.79 | H32: =E32-G32 -> -82261.043 | L32: Nov-2026 | M32: 886858.74 | N32: 969119.79 | O32: -82261.043
B33: Dec-2026 | C33: 833333.33 | D33: 104.3102 | E33: =D33*100000/12 -> 869251.64 | F33: 112.06867 | G33: 933905.58 | H33: =E33-G33 -> -64653.94 | L33: Dec-2026 | M33: 869251.64 | N33: 933905.58 | O33: -64653.94
D36: Exchange Rate to Profit Adverse | M36: Monthly Hedging Impact @ Adverse Exchange Rate
B38: Date | C38: Base monthly Profit | D38: hedged Profit | E38: Hedged Monthly Profit | F38: UnHedged Profit | G38: UnHedged Monthly Profit | H38: Monthly Hedging Impact | L38: Date | M38: Hedged Monthly Profit | N38: UnHedged Monthly Profit | O38: Hedging Impact
B39: Jan-2026 | C39: 833333.33 | D39: 82.219075 | E39: =D39*100000/12 -> 685158.96 | F39: 67.886425 | G39: 565720.21 | H39: =E39-G39 -> 119438.74 | L39: Jan-2026 | M39: 685158.96 | N39: 565720.21 | O39: 119438.74
B40: Feb-2026 | C40: 833333.33 | D40: 78.55489 | E40: =D40*100000/12 -> 654624.08 | F40: 60.558055 | G40: 504650.46 | H40: =E40-G40 -> 149973.62 | L40: Feb-2026 | M40: 654624.08 | N40: 504650.46 | O40: 149973.62
B41: Mar-2026 | C41: 833333.33 | D41: 79.404512 | E41: =D41*100000/12 -> 661704.27 | F41: 62.257301 | G41: 518810.84 | H41: =E41-G41 -> 142893.43 | L41: Mar-2026 | M41: 661704.27 | N41: 518810.84 | O41: 142893.43
B42: Apr-2026 | C42: 833333.33 | D42: 80.40509 | E42: =D42*100000/12 -> 670042.42 | F42: 64.258456 | G42: 535487.14 | H42: =E42-G42 -> 134555.28 | L42: Apr-2026 | M42: 670042.42 | N42: 535487.14 | O42: 134555.28
B43: May-2026 | C43: 833333.33 | D43: 79.438561 | E43: =D43*100000/12 -> 661988.01 | F43: 62.325398 | G43: 519378.32 | H43: =E43-G43 -> 142609.69 | L43: May-2026 | M43: 661988.01 | N43: 519378.32 | O43: 142609.69
B44: Jun-2026 | C44: 833333.33 | D44: 77.577297 | E44: =D44*100000/12 -> 646477.48 | F44: 58.602871 | G44: 488357.26 | H44: =E44-G44 -> 158120.22 | L44: Jun-2026 | M44: 646477.48 | N44: 488357.26 | O44: 158120.22
B45: Jul-2026 | C45: 833333.33 | D45: 79.341777 | E45: =D45*100000/12 -> 661181.48 | F45: 62.13183 | G45: 517765.25 | H45: =E45-G45 -> 143416.22 | L45: Jul-2026 | M45: 661181.48 | N45: 517765.25 | O45: 143416.22
B46: Aug-2026 | C46: 833333.33 | D46: 78.34033 | E46: =D46*100000/12 -> 652836.08 | F46: 60.128935 | G46: 501074.46 | H46: =E46-G46 -> 151761.62 | L46: Aug-2026 | M46: 652836.08 | N46: 501074.46 | O46: 151761.62
B47: Sep-2026 | C47: 833333.33 | D47: 76.92951 | E47: =D47*100000/12 -> 641079.25 | F47: 57.307296 | G47: 477560.8 | H47: =E47-G47 -> 163518.45 | L47: Sep-2026 | M47: 641079.25 | N47: 477560.8 | O47: 163518.45
B48: Oct-2026 | C48: 833333.33 | D48: 76.329111 | E48: =D48*100000/12 -> 636075.93 | F48: 56.106499 | G48: 467554.15 | H48: =E48-G48 -> 168521.77 | L48: Oct-2026 | M48: 636075.93 | N48: 467554.15 | O48: 168521.77
...

Sheet Quarterly Hedging Effect
N2: Worst Period Profit
C3: Exchange Rate to Profit Base
N4: Scenarios | O4: Unhedged Profit | P4: Hedged Profit | Q4: Hedging impact
B5: Quarters | C5: hedged Profit | D5: UnHedged Profit | E5: Hedging Impact | F5: Hedging Imapct % | H5: Net annual Hedging Benefit | L5: =SUM(E6:E9) -> 822875.67 | N5: Base | O5: =MIN(D6:D9) -> 1865417.9 | P5: =MIN(C6:C9) -> 2139605.5 | Q5: =P5-O5 -> 274187.61
B6: 1 | C6: =SUM('Monthly Hedging Impact'!E5:E7) -> 2139605.5 | D6: =SUM('Per Unit & Monthly FX Impact'!N6:N8) -> 1865417.9 | E6: =C6-D6 -> 274187.61 | F6: =E6/D6 -> 0.14698455 | H6: Worst Quarter Protection in ₹ | L6: =MAX(E6:E9) -> 274187.61 | N6: Favourable | O6: =MIN(D17:D20) -> 2141654.3 | P6: =MIN(C17:C20) -> 2277723.7 | Q6: =P6-O6 -> 136069.43
B7: 2 | C7: =SUM('Monthly Hedging Impact'!E8:E10) -> 2194895.8 | D7: =SUM('Per Unit & Monthly FX Impact'!N9:N11) -> 1975998.5 | E7: =C7-D7 -> 218897.28 | F7: =E7/D7 -> 0.11077806 | H7: % of FX Loss Recovered By Hedging | L7: =L6/'Quarterly FX Impact'!K5*-1 -> 0.43207585 | N7: Adverse | O7: =MIN(D28:D31) -> 1320981.5 | P7: =MIN(C28:C31) -> 1867387.3 | Q7: =P7-O7 -> 546405.8
B8: 3 | C8: =SUM('Monthly Hedging Impact'!E11:E13) -> 2251038.9 | D8: =SUM('Per Unit & Monthly FX Impact'!N12:N14) -> 2088284.6 | E8: =C8-D8 -> 162754.23 | F8: =E8/D8 -> 0.077936804 | H8: Volatility Under Hedging | L8: =MAX(E6:E9)-MIN(E6:E9) -> 111433.38
B9: 4 | C9: =SUM('Monthly Hedging Impact'!E14:E16) -> 2246756.6 | D9: =SUM('Per Unit & Monthly FX Impact'!N15:N17) -> 2079720 | E9: =C9-D9 -> 167036.55 | F9: =E9/D9 -> 0.080316844 | H9: Volatility Under FX | L9: 222866.76
H10: Volatility Reduction % | L10: =L8/L9 -> 0.5 | N10: =MAX(D6:D9) -> 2088284.6
N11: =MIN(D6:D9) -> 1865417.9
C14: Exchange Rate to Profit Favourable
B16: Quarters | C16: hedged Profit | D16: UnHedged Profit | E16: Hedging Impact | F16: Hedging Imapct % | H16: Net annual Hedging Benefit | L16: =SUM(E17:E20) -> -206941.74
B17: 1 | C17: =SUM('Monthly Hedging Impact'!E22:E24) -> 2277723.7 | D17: 2141654.3 | E17: =C17-D17 -> 136069.43 | F17: =E17/D17 -> 0.063534731 | H17: Worst Quarter Protection in ₹ | L17: =MAX(E17:E20) -> 136069.43
B18: 2 | C18: =SUM('Monthly Hedging Impact'!E25:E27) -> 2411283.7 | D18: 2408774.4 | E18: =C18-D18 -> 2509.3697 | F18: =E18/D18 -> 0.001041762 | H18: % of FX Loss Recovered By Hedging | L18: =L17/'Quarterly FX Impact'!K14*-1 -> 0.37971548
B19: 3 | C19: =SUM('Monthly Hedging Impact'!E28:E30) -> 2546980.9 | D19: 2680168.8 | E19: =C19-D19 -> -133187.83 | F19: =E19/D19 -> -0.049693823 | H19: Volatility Under Hedging | L19: =MAX(E17:E20)-MIN(E17:E20) -> 348402.14
B20: 4 | C20: =SUM('Monthly Hedging Impact'!E31:E33) -> 2626125.8 | D20: 2838458.5 | E20: =C20-D20 -> -212332.71 | F20: =E20/D20 -> -0.074805641 | H20: Volatility Under FX | L20: 696804.27
H21: Volatility Reduction % | L21: =L19/L20 -> 0.5 | N21: =MAX(D17:D20) -> 2838458.5
N22: =MIN(D17:D20) -> 2141654.3
C25: Exchange Rate to Profit Adverse
B27: Quarters | C27: hedged Profit | D27: UnHedged Profit | E27: Hedging Impact | F27: Hedging Imapct % | H27: Net annual Hedging Benefit | L27: =SUM(E28:E31) -> 1852693.1
B28: 1 | C28: =SUM('Monthly Hedging Impact'!E39:E41) -> 2001487.3 | D28: 1589181.5 | E28: =C28-D28 -> 412305.8 | F28: =E28/D28 -> 0.25944538 | H28: Worst Quarter Protection in ₹ | L28: =MAX(E28:E31) -> 546405.8 | N28: =MAX(C28:C31) -> 2001487.3
B29: 2 | C29: =SUM('Monthly Hedging Impact'!E42:E44) -> 1978507.9 | D29: 1543222.7 | E29: =C29-D29 -> 435285.2 | F29: =E29/D29 -> 0.28206246 | H29: % of FX Loss Recovered By Hedging | L29: =L28/'Quarterly FX Impact'!K22*-1 -> 0.46344125 | N29: =MIN(C28:C31) -> 1867387.3
B30: 3 | C30: =SUM('Monthly Hedging Impact'!E45:E47) -> 1955096.8 | D30: 1496400.5 | E30: =C30-D30 -> 458696.29 | F30: =E30/D30 -> 0.3065331 | H30: Volatility Under Hedging | L30: =MAX(E28:E31)-MIN(E28:E31) -> 134100.01
B31: 4 | C31: =SUM('Monthly Hedging Impact'!E48:E50) -> 1867387.3 | D31: 1320981.5 | E31: =C31-D31 -> 546405.8 | F31: =E31/D31 -> 0.41363623 | H31: Volatility Under FX | L31: 268200.01
H32: Volatility Reduction % | L32: =L30/L31 -> 0.5 | N32: =MAX(D28:D31) -> 1589181.5
N33: =MIN(D28:D31) -> 1320981.5
